<?xml version="1.0" ?>
<robot name="wheelbase" xmlns:xacro="http://www.ros.org/wiki/xacro">

<xacro:include filename="$(find wheelbase_description)/models/urdf/materials.xacro" />
<!-- <xacro:include filename="$(find wheelbase_description)/models/urdf/wheelbase.trans" /> -->
<xacro:include filename="$(find wheelbase_gazebo)/gazebo/wheelbase_materials.gazebo" />
<xacro:include filename="$(find wheelbase_gazebo)/gazebo/wheelbase_plugins.gazebo" />
<xacro:include filename="$(find wheelbase_gazebo)/gazebo/wheelbase_physics.gazebo" />


<link name="base_link">
  <inertial>
    <origin xyz="4.877641986557568e-16 -0.018658552355966238 0.08278725001137692" rpy="0 0 0"/>
    <mass value="3.805688673818861"/>
    <inertia ixx="0.063163" iyy="0.054403" izz="0.117281" ixy="0.0" iyz="-0.000489" ixz="0.0"/>
  </inertial>
  <visual>
    <origin xyz="0 0 0" rpy="0 0 0"/>
    <geometry>
      <mesh filename="$(find wheelbase_description)/models/meshes/base_link.stl" scale="0.001 0.001 0.001"/>
    </geometry>
    <material name="silver"/>
  </visual>
  <collision>
    <origin xyz="0 0 0" rpy="0 0 0"/>
    <geometry>
      <mesh filename="$(find wheelbase_description)/models/meshes/base_link.stl" scale="0.001 0.001 0.001"/>
    </geometry>
  </collision>
</link>

<link name="blbody_1">
  <inertial>
    <origin xyz="0.00014938972183493882 -0.007359677627955308 -0.013592300867627055" rpy="0 0 0"/>
    <mass value="0.19014627005982346"/>
    <inertia ixx="8.5e-05" iyy="7.3e-05" izz="7.6e-05" ixy="1e-06" iyz="-2.6e-05" ixz="1e-06"/>
  </inertial>
  <visual>
    <origin xyz="0.0775 0.133688 -0.074672" rpy="0 0 0"/>
    <geometry>
      <mesh filename="$(find wheelbase_description)/models/meshes/blbody_1.stl" scale="0.001 0.001 0.001"/>
    </geometry>
    <material name="silver"/>
  </visual>
  <collision>
    <origin xyz="0.0775 0.133688 -0.074672" rpy="0 0 0"/>
    <geometry>
      <mesh filename="$(find wheelbase_description)/models/meshes/blbody_1.stl" scale="0.001 0.001 0.001"/>
    </geometry>
  </collision>
</link>

<link name="brbody_1">
  <inertial>
    <origin xyz="0.00014939157119377156 -0.007359677627955363 -0.013592300867627097" rpy="0 0 0"/>
    <mass value="0.19014627005982263"/>
    <inertia ixx="8.5e-05" iyy="7.3e-05" izz="7.6e-05" ixy="1e-06" iyz="-2.6e-05" ixz="1e-06"/>
  </inertial>
  <visual>
    <origin xyz="-0.0775 0.133688 -0.074672" rpy="0 0 0"/>
    <geometry>
      <mesh filename="$(find wheelbase_description)/models/meshes/brbody_1.stl" scale="0.001 0.001 0.001"/>
    </geometry>
    <material name="silver"/>
  </visual>
  <collision>
    <origin xyz="-0.0775 0.133688 -0.074672" rpy="0 0 0"/>
    <geometry>
      <mesh filename="$(find wheelbase_description)/models/meshes/brbody_1.stl" scale="0.001 0.001 0.001"/>
    </geometry>
  </collision>
</link>

<link name="flbody_1">
  <inertial>
    <origin xyz="0.0001493896602373368 -0.007371286050261883 -0.013586022157761626" rpy="0 0 0"/>
    <mass value="0.19014627109702392"/>
    <inertia ixx="8.5e-05" iyy="7.2e-05" izz="7.6e-05" ixy="1e-06" iyz="-2.6e-05" ixz="1e-06"/>
  </inertial>
  <visual>
    <origin xyz="0.07798 -0.134335 -0.074428" rpy="0 0 0"/>
    <geometry>
      <mesh filename="$(find wheelbase_description)/models/meshes/flbody_1.stl" scale="0.001 0.001 0.001"/>
    </geometry>
    <material name="silver"/>
  </visual>
  <collision>
    <origin xyz="0.07798 -0.134335 -0.074428" rpy="0 0 0"/>
    <geometry>
      <mesh filename="$(find wheelbase_description)/models/meshes/flbody_1.stl" scale="0.001 0.001 0.001"/>
    </geometry>
  </collision>
</link>

<link name="frbody_1">
  <inertial>
    <origin xyz="0.00014939154224478945 -0.0073364432145827385 -0.013604729372114231" rpy="0 0 0"/>
    <mass value="0.19014627066064962"/>
    <inertia ixx="8.5e-05" iyy="7.3e-05" izz="7.6e-05" ixy="1e-06" iyz="-2.6e-05" ixz="1e-06"/>
  </inertial>
  <visual>
    <origin xyz="-0.07702 -0.13438 -0.074773" rpy="0 0 0"/>
    <geometry>
      <mesh filename="$(find wheelbase_description)/models/meshes/frbody_1.stl" scale="0.001 0.001 0.001"/>
    </geometry>
    <material name="silver"/>
  </visual>
  <collision>
    <origin xyz="-0.07702 -0.13438 -0.074773" rpy="0 0 0"/>
    <geometry>
      <mesh filename="$(find wheelbase_description)/models/meshes/frbody_1.stl" scale="0.001 0.001 0.001"/>
    </geometry>
  </collision>
</link>

<link name="flwheel_1">
  <inertial>
    <origin xyz="0.011664000000000271 4.85031257532742e-07 3.2883506063258183e-07" rpy="0 0 0"/>
    <mass value="0.4002742105569766"/>
    <inertia ixx="0.000177" iyy="0.000105" izz="0.000105" ixy="-0.0" iyz="-0.0" ixz="0.0"/>
  </inertial>
  <visual>
    <origin xyz="0.089644 -0.107 -0.032259" rpy="0 0 0"/>
    <geometry>
      <mesh filename="$(find wheelbase_description)/models/meshes/flwheel_1.stl" scale="0.001 0.001 0.001"/>
    </geometry>
    <material name="silver"/>
  </visual>
  <collision>
    <origin xyz="0.089644 -0.107 -0.032259" rpy="0 0 0"/>
    <geometry>
      <mesh filename="$(find wheelbase_description)/models/meshes/flwheel_1.stl" scale="0.001 0.001 0.001"/>
    </geometry>
  </collision>
</link>

<link name="frwheel_1">
  <inertial>
    <origin xyz="0.011663999999999827 8.189762357169172e-08 2.5024366512998997e-07" rpy="0 0 0"/>
    <mass value="0.4002742105569771"/>
    <inertia ixx="0.000177" iyy="0.000105" izz="0.000105" ixy="-0.0" iyz="0.0" ixz="0.0"/>
  </inertial>
  <visual>
    <origin xyz="-0.065356 -0.107154 -0.032534" rpy="0 0 0"/>
    <geometry>
      <mesh filename="$(find wheelbase_description)/models/meshes/frwheel_1.stl" scale="0.001 0.001 0.001"/>
    </geometry>
    <material name="silver"/>
  </visual>
  <collision>
    <origin xyz="-0.065356 -0.107154 -0.032534" rpy="0 0 0"/>
    <geometry>
      <mesh filename="$(find wheelbase_description)/models/meshes/frwheel_1.stl" scale="0.001 0.001 0.001"/>
    </geometry>
  </collision>
</link>

<link name="brwheel_1">
  <inertial>
    <origin xyz="-0.011664000000000077 -2.9881071383908164e-07 -4.217513900617309e-07" rpy="0 0 0"/>
    <mass value="0.40027421055697693"/>
    <inertia ixx="0.000177" iyy="0.000105" izz="0.000105" ixy="-0.0" iyz="-0.0" ixz="0.0"/>
  </inertial>
  <visual>
    <origin xyz="-0.089164 0.160987 -0.032481" rpy="0 0 0"/>
    <geometry>
      <mesh filename="$(find wheelbase_description)/models/meshes/brwheel_1.stl" scale="0.001 0.001 0.001"/>
    </geometry>
    <material name="silver"/>
  </visual>
  <collision>
    <origin xyz="-0.089164 0.160987 -0.032481" rpy="0 0 0"/>
    <geometry>
      <mesh filename="$(find wheelbase_description)/models/meshes/brwheel_1.stl" scale="0.001 0.001 0.001"/>
    </geometry>
  </collision>
</link>

<link name="blwheel_1">
  <inertial>
    <origin xyz="-0.011664000000000133 -2.988107136447926e-07 -4.217513900617309e-07" rpy="0 0 0"/>
    <mass value="0.4002742105569769"/>
    <inertia ixx="0.000177" iyy="0.000105" izz="0.000105" ixy="-0.0" iyz="-0.0" ixz="0.0"/>
  </inertial>
  <visual>
    <origin xyz="0.065836 0.160987 -0.032481" rpy="0 0 0"/>
    <geometry>
      <mesh filename="$(find wheelbase_description)/models/meshes/blwheel_1.stl" scale="0.001 0.001 0.001"/>
    </geometry>
    <material name="silver"/>
  </visual>
  <collision>
    <origin xyz="0.065836 0.160987 -0.032481" rpy="0 0 0"/>
    <geometry>
      <mesh filename="$(find wheelbase_description)/models/meshes/blwheel_1.stl" scale="0.001 0.001 0.001"/>
    </geometry>
  </collision>
</link>

<link name="lmwheel_1">
  <inertial>
    <origin xyz="-0.02451118669748789 -4.022434244760521e-07 2.780890716314044e-08" rpy="0 0 0"/>
    <mass value="0.2558759862973169"/>
    <inertia ixx="0.000296" iyy="0.000205" izz="0.000205" ixy="-0.0" iyz="-0.0" ixz="-0.0"/>
  </inertial>
  <visual>
    <origin xyz="0.157 -8.4e-05 -0.053747" rpy="0 0 0"/>
    <geometry>
      <mesh filename="$(find wheelbase_description)/models/meshes/lmwheel_1.stl" scale="0.001 0.001 0.001"/>
    </geometry>
    <material name="silver"/>
  </visual>
  <collision>
    <origin xyz="0.157 -8.4e-05 -0.053747" rpy="0 0 0"/>
    <geometry>
      <mesh filename="$(find wheelbase_description)/models/meshes/lmwheel_1.stl" scale="0.001 0.001 0.001"/>
    </geometry>
  </collision>
</link>

<link name="rmwheel_1">
  <inertial>
    <origin xyz="0.024511186697488335 1.5354622580527905e-07 2.402273406934552e-07" rpy="0 0 0"/>
    <mass value="0.2558759862973067"/>
    <inertia ixx="0.000296" iyy="0.000205" izz="0.000205" ixy="0.0" iyz="0.0" ixz="0.0"/>
  </inertial>
  <visual>
    <origin xyz="-0.157 -0.000182 -0.053746" rpy="0 0 0"/>
    <geometry>
      <mesh filename="$(find wheelbase_description)/models/meshes/rmwheel_1.stl" scale="0.001 0.001 0.001"/>
    </geometry>
    <material name="silver"/>
  </visual>
  <collision>
    <origin xyz="-0.157 -0.000182 -0.053746" rpy="0 0 0"/>
    <geometry>
      <mesh filename="$(find wheelbase_description)/models/meshes/rmwheel_1.stl" scale="0.001 0.001 0.001"/>
    </geometry>
  </collision>
</link>

<link name="l_m_clamp_1">
  <inertial>
    <origin xyz="0.05064998589086303 -0.04461412871917579 -0.04614971479491306" rpy="0 0 0"/>
    <mass value="1.781612993557575"/>
    <inertia ixx="0.006616" iyy="0.002696" izz="0.007336" ixy="0.000109" iyz="-0.001506" ixz="0.000421"/>
  </inertial>
  <visual>
    <origin xyz="0.1395 -0.076797 -0.11294" rpy="0 0 0"/>
    <geometry>
      <mesh filename="$(find wheelbase_description)/models/meshes/l_m_clamp_1.stl" scale="0.001 0.001 0.001"/>
    </geometry>
    <material name="silver"/>
  </visual>
  <collision>
    <origin xyz="0.1395 -0.076797 -0.11294" rpy="0 0 0"/>
    <geometry>
      <mesh filename="$(find wheelbase_description)/models/meshes/l_m_clamp_1.stl" scale="0.001 0.001 0.001"/>
    </geometry>
  </collision>
</link>

<link name="r_m_clamp_1">
  <inertial>
    <origin xyz="-0.05056459586676207 -0.045464553847886925 -0.046249593954142215" rpy="0 0 0"/>
    <mass value="1.7657597378662766"/>
    <inertia ixx="0.006433" iyy="0.002681" izz="0.007143" ixy="-0.000124" iyz="-0.001487" ixz="-0.000423"/>
  </inertial>
  <visual>
    <origin xyz="-0.1395 -0.076797 -0.11294" rpy="0 0 0"/>
    <geometry>
      <mesh filename="$(find wheelbase_description)/models/meshes/r_m_clamp_1.stl" scale="0.001 0.001 0.001"/>
    </geometry>
    <material name="silver"/>
  </visual>
  <collision>
    <origin xyz="-0.1395 -0.076797 -0.11294" rpy="0 0 0"/>
    <geometry>
      <mesh filename="$(find wheelbase_description)/models/meshes/r_m_clamp_1.stl" scale="0.001 0.001 0.001"/>
    </geometry>
  </collision>
</link>

<link name="topcover_1">
  <inertial>
    <origin xyz="-2.8402894336812473e-05 0.006380708957092697 0.08894790371795151" rpy="0 0 0"/>
    <mass value="0.9083298747068661"/>
    <inertia ixx="0.021829" iyy="0.020969" izz="0.040194" ixy="4e-06" iyz="-0.000268" ixz="1e-06"/>
  </inertial>
  <visual>
    <origin xyz="0.0 -6.6e-05 -0.083" rpy="0 0 0"/>
    <geometry>
      <mesh filename="$(find wheelbase_description)/models/meshes/topcover_1.stl" scale="0.001 0.001 0.001"/>
    </geometry>
    <material name="silver"/>
  </visual>
  <collision>
    <origin xyz="0.0 -6.6e-05 -0.083" rpy="0 0 0"/>
    <geometry>
      <mesh filename="$(find wheelbase_description)/models/meshes/topcover_1.stl" scale="0.001 0.001 0.001"/>
    </geometry>
  </collision>
</link>

<link name="basecover_1">
  <inertial>
    <origin xyz="4.306271547693276e-08 -1.3417406008355676e-06 -0.041449190774674516" rpy="0 0 0"/>
    <mass value="8.26904328209992"/>
    <inertia ixx="0.164421" iyy="0.172326" izz="0.330566" ixy="0.0" iyz="0.0" ixz="0.0"/>
  </inertial>
  <visual>
    <origin xyz="0.0 -6.6e-05 -0.083" rpy="0 0 0"/>
    <geometry>
      <mesh filename="$(find wheelbase_description)/models/meshes/basecover_1.stl" scale="0.001 0.001 0.001"/>
    </geometry>
    <material name="silver"/>
  </visual>
  <collision>
    <origin xyz="0.0 -6.6e-05 -0.083" rpy="0 0 0"/>
    <geometry>
      <mesh filename="$(find wheelbase_description)/models/meshes/basecover_1.stl" scale="0.001 0.001 0.001"/>
    </geometry>
  </collision>
</link>

<link name="lidar_1">
  <inertial>
    <origin xyz="-0.001262937955366997 0.0019039619404818409 -0.013950427004351534" rpy="0 0 0"/>
    <mass value="0.17388739461388325"/>
    <inertia ixx="7.5e-05" iyy="7.9e-05" izz="0.000125" ixy="0.0" iyz="-2e-06" ixz="1e-06"/>
  </inertial>
  <visual>
    <origin xyz="0.0005 -0.170623 -0.251375" rpy="0 0 0"/>
    <geometry>
      <mesh filename="$(find wheelbase_description)/models/meshes/lidar_1.stl" scale="0.001 0.001 0.001"/>
    </geometry>
    <material name="silver"/>
  </visual>
  <collision>
    <origin xyz="0.0005 -0.170623 -0.251375" rpy="0 0 0"/>
    <geometry>
      <mesh filename="$(find wheelbase_description)/models/meshes/lidar_1.stl" scale="0.001 0.001 0.001"/>
    </geometry>
  </collision>
</link>

<joint name="bl_swivel" type="continuous">
  <origin xyz="-0.0775 -0.133688 0.074672" rpy="0 0 0"/>
  <parent link="base_link"/>
  <child link="blbody_1"/>
  <axis xyz="0.0 -0.0 -1.0"/>
</joint>

<joint name="br_swivel" type="continuous">
  <origin xyz="0.0775 -0.133688 0.074672" rpy="0 0 0"/>
  <parent link="base_link"/>
  <child link="brbody_1"/>
  <axis xyz="0.0 -0.0 -1.0"/>
</joint>

<joint name="fl_swivel" type="continuous">
  <origin xyz="0.06152 0.057538 -0.038512" rpy="0 0 0"/>
  <parent link="l_m_clamp_1"/>
  <child link="flbody_1"/>
  <axis xyz="0.0 -0.000826 -1.0"/>
</joint>

<joint name="fr_swivel" type="continuous">
  <origin xyz="-0.06248 0.057583 -0.038167" rpy="0 0 0"/>
  <parent link="r_m_clamp_1"/>
  <child link="frbody_1"/>
  <axis xyz="0.0 0.001752 -0.999998"/>
</joint>

<joint name="fl_wheel" type="continuous">
  <origin xyz="-0.011664 -0.027335 -0.042169" rpy="0 0 0"/>
  <parent link="flbody_1"/>
  <child link="flwheel_1"/>
  <axis xyz="1.0 -0.0 0.0"/>
</joint>

<joint name="fr_wheel" type="continuous">
  <origin xyz="-0.011664 -0.027226 -0.042239" rpy="0 0 0"/>
  <parent link="frbody_1"/>
  <child link="frwheel_1"/>
  <axis xyz="1.0 -0.0 0.0"/>
</joint>

<joint name="br_wheel" type="continuous">
  <origin xyz="0.011664 -0.027299 -0.042191" rpy="0 0 0"/>
  <parent link="brbody_1"/>
  <child link="brwheel_1"/>
  <axis xyz="1.0 0.0 0.0"/>
</joint>

<joint name="bl_wheel" type="continuous">
  <origin xyz="0.011664 -0.027299 -0.042191" rpy="0 0 0"/>
  <parent link="blbody_1"/>
  <child link="blwheel_1"/>
  <axis xyz="1.0 0.0 0.0"/>
</joint>

<joint name="lm_wheel" type="continuous">
  <origin xyz="-0.0175 -0.076713 -0.059193" rpy="0 0 0"/>
  <parent link="l_m_clamp_1"/>
  <child link="lmwheel_1"/>
  <axis xyz="-1.0 0.0 0.0"/>
</joint>

<joint name="rm_wheel" type="continuous">
  <origin xyz="0.0175 -0.076615 -0.059194" rpy="0 0 0"/>
  <parent link="r_m_clamp_1"/>
  <child link="rmwheel_1"/>
  <axis xyz="-1.0 0.0 0.0"/>
</joint>

<joint name="l_clamp" type="revolute">
  <origin xyz="-0.1395 0.076797 0.11294" rpy="0 0 0"/>
  <parent link="base_link"/>
  <child link="l_m_clamp_1"/>
  <axis xyz="1.0 0.0 0.0"/>
  <limit upper="0.174533" lower="-0.174533" effort="100" velocity="100"/>
</joint>

<joint name="r_clamp" type="revolute">
  <origin xyz="0.1395 0.076797 0.11294" rpy="0 0 0"/>
  <parent link="base_link"/>
  <child link="r_m_clamp_1"/>
  <axis xyz="1.0 -0.0 -0.0"/>
  <limit upper="0.174533" lower="-0.174533" effort="100" velocity="100"/>
</joint>

<joint name="topcover" type="fixed">
  <origin xyz="0.0 6.6e-05 0.083" rpy="0 0 0"/>
  <parent link="base_link"/>
  <child link="topcover_1"/>
</joint>

<joint name="basecover" type="fixed">
  <origin xyz="0.0 6.6e-05 0.083" rpy="0 0 0"/>
  <parent link="base_link"/>
  <child link="basecover_1"/>
</joint>

<joint name="lidar_joint" type="continuous">
  <origin xyz="-0.0005 0.170557 0.168375" rpy="0 0 0"/>
  <parent link="topcover_1"/>
  <child link="lidar_1"/>
  <axis xyz="0.0 0.0 1.0"/>
</joint>

</robot>
